Workbook

Sheet 01-核心假设
A1: 今夜树屋 · 收入模型 — 核心假设(黄色单元格均可修改, 全簿联动)
A2: 所有定价来自 PRD v1.0; 渗透率/付费率为运营假设, 可随真实数据回测校准。
A3: 一、全局参数
A4: 每月天数(天) | B4: 30 | C4: 按自然月计
A5: 基准 DAU(模型计算档) | B5: 5000 | C5: PRD 3 个月目标 DAU 5000
A6: 目标付费率(对标 PRD) | B6: 0.03 | C6: PRD 成功指标 ≥3%
A7: 目标 ARPU(元/月, 对标 PRD) | B7: 8 | C7: PRD 成功指标 ≥8 元
A8: 会员月卡价格(元) | B8: 19 | C8: PRD 定价 19 元/月
A9: 会员年卡价格(元) | B9: 128 | C9: PRD 定价 128 元/年
A10: 会员月均摊销 ARPU(元) | B10: =B8*B11+B9/12*(1-B11) | C10: 月卡按 19 计, 年卡按 128/12 摊销
A11: 会员中月卡购买占比 | B11: 0.7 | C11: 假设 70% 买月卡、30% 买年卡
A13: 二、DAU 分档假设
A14: 档位 | B14: DAU | C14: 说明
A15: 保守 | B15: 1000 | C15: 冷启动后低位运行
A16: 低速 | B16: 3000 | C16: 未达成 PRD 目标
A17: 目标 | B17: 5000 | C17: PRD 3 个月目标
A18: 乐观 | B18: 10000 | C18: 裂变超预期
A20: 三、模块渗透率假设(DAU 中每日进入该模块的比例)
A21: 模块 | B21: 名称 | C21: 日渗透率 | D21: 依据
A22: A | B22: 深夜信箱 📮 | C22: 0.25 | D22: 写信+回信, 情绪浓度高但频次中等
A23: B | B23: 摆烂许可证 🪑 | C23: 0.4 | D23: 一键领取+分享, 门槛最低的流量入口
A24: C | B24: 塔罗盲盒 🔮 | C24: 0.2 | D24: 每日一张免费抽牌, 强仪式感
A25: D | B25: 许愿池 🕯 | C25: 0.3 | D25: 敲木鱼+签到, 高频轻互动
A26: E | B26: 漂流墙 💌 | C26: 0.35 | D26: 刷墙无成本, 浏览型流量
A28: 四、会员与成本假设
A29: 会员转化率目标(PRD ≥1.5%) | B29: 0.015 | C29: 付费会员 / DAU
A30: LLM 单次调用成本(元) | B30: 0.02 | C30: DeepSeek 级 API 均价, 含回信/解读/祝福信
A31: 日人均 AI 互动率 | B31: 0.4 | C31: DAU 中触发 AI 功能的用户占比
A32: 日人均 AI 调用次数(次) | B32: 1.5 | C32: 触发用户平均调用次数
A33: 内容审核单价(元/条) | B33: 0.0015 | C33: 微信内容安全 API 量级
A34: 日人均 UGC 条数(条) | B34: 0.16 | C34: 约 8% 用户日均发 2 条
A35: 微信支付通道费率 | B35: 0.006 | C35: 微信支付标准费率 0.6%
A37: 五、服务器成本分档(元/月)
A38: DAU 上限 | B38: 月成本(元)
A39: 1000 | B39: 300
A40: 3000 | B40: 500
A41: 5000 | B41: 800
A42: 10000 | B42: 1500
A43: 999999 | B43: 3000
A44: 图例: 淡黄色 = 可调假设; 其余为公式或说明。

Sheet 02-模块收入模型
A1: 02 · 模块收入模型 — 单点付费(按基准 DAU 计算)
A2: 日付费人数 = 基准DAU × 模块渗透率 × 该付费点日付费率; 月流水 = 单价 × 日付费人数 × 每月天数。黄色为可调假设。
A3: 模块 | B3: 付费点 | C3: 单价(元) | D3: 日付费率(占模块访客) | E3: 日付费人数 | F3: 日流水(元) | G3: 月流水(元) | H3: 定价来源(PRD)
A4: A · 深夜信箱 📮 | B4: AI 深度回信(500字含心理分析) | C4: 4.9 | D4: 0.02 | E4: ='01-核心假设'!$B$5*'01-核心假设'!$C$22*D4 | F4: =C4*E4 | G4: =F4*'01-核心假设'!$B$4 | H4: 4.9 元/封
B5: 定制人格回信(如爱豆口吻) | C5: 9.9 | D5: 0.008 | E5: ='01-核心假设'!$B$5*'01-核心假设'!$C$22*D5 | F5: =C5*E5 | G5: =F5*'01-核心假设'!$B$4 | H5: 9.9 元/封
A6: A 小计 | E6: =SUM(E4:E5) | F6: =SUM(F4:F5) | G6: =SUM(G4:G5)
A7: B · 摆烂许可证 🪑 | B7: 高级许可证模板(企业/古风/赛博/宫廷) | C7: 3 | D7: 0.015 | E7: ='01-核心假设'!$B$5*'01-核心假设'!$C$23*D7 | F7: =C7*E7 | G7: =F7*'01-核心假设'!$B$4 | H7: 3 元/张
B8: 定制头像+姓名专属证书 | C8: 6.9 | D8: 0.005 | E8: ='01-核心假设'!$B$5*'01-核心假设'!$C$23*D8 | F8: =C8*E8 | G8: =F8*'01-核心假设'!$B$4 | H8: 6.9 元
B9: 周边·真实印刷明信片(含邮费) | C9: 9.9 | D9: 0.002 | E9: ='01-核心假设'!$B$5*'01-核心假设'!$C$23*D9 | F9: =C9*E9 | G9: =F9*'01-核心假设'!$B$4 | H9: 9.9 元
A10: B 小计 | E10: =SUM(E7:E9) | F10: =SUM(F7:F9) | G10: =SUM(G7:G9)
A11: C · 塔罗盲盒 🔮 | B11: 三牌阵(过去/现在/未来) | C11: 9.9 | D11: 0.012 | E11: ='01-核心假设'!$B$5*'01-核心假设'!$C$24*D11 | F11: =C11*E11 | G11: =F11*'01-核心假设'!$B$4 | H11: 9.9 元
B12: 深度解读-标准档 | C12: 19.9 | D12: 0.006 | E12: ='01-核心假设'!$B$5*'01-核心假设'!$C$24*D12 | F12: =C12*E12 | G12: =F12*'01-核心假设'!$B$4 | H12: 19.9~68 元区间下限
B13: 深度解读-旗舰档 | C13: 68 | D13: 0.001 | E13: ='01-核心假设'!$B$5*'01-核心假设'!$C$24*D13 | F13: =C13*E13 | G13: =F13*'01-核心假设'!$B$4 | H13: 19.9~68 元区间上限
B14: 情感专题牌阵-标准档 | C14: 29.9 | D14: 0.004 | E14: ='01-核心假设'!$B$5*'01-核心假设'!$C$24*D14 | F14: =C14*E14 | G14: =F14*'01-核心假设'!$B$4 | H14: 29.9~99 元区间下限
B15: 情感专题牌阵-豪华档 | C15: 99 | D15: 0.001 | E15: ='01-核心假设'!$B$5*'01-核心假设'!$C$24*D15 | F15: =C15*E15 | G15: =F15*'01-核心假设'!$B$4 | H15: 29.9~99 元区间上限
B16: 年度塔罗报告(生日/元旦) | C16: 99 | D16: 0.0005 | E16: ='01-核心假设'!$B$5*'01-核心假设'!$C$24*D16 | F16: =C16*E16 | G16: =F16*'01-核心假设'!$B$4 | H16: 99 元(年化到日均)
A17: C 小计 | E17: =SUM(E11:E16) | F17: =SUM(F11:F16) | G17: =SUM(G11:G16)
A18: D · 许愿池 🕯 | B18: 高级木鱼皮肤(金色/水晶/敦煌) | C18: 6 | D18: 0.008 | E18: ='01-核心假设'!$B$5*'01-核心假设'!$C$25*D18 | F18: =C18*E18 | G18: =F18*'01-核心假设'!$B$4 | H18: 6 元
B19: 结愿仪式(AI 心愿达成祝福信) | C19: 4.9 | D19: 0.01 | E19: ='01-核心假设'!$B$5*'01-核心假设'!$C$25*D19 | F19: =C19*E19 | G19: =F19*'01-核心假设'!$B$4 | H19: 4.9 元
A20: D 小计 | E20: =SUM(E18:E19) | F20: =SUM(F18:F19) | G20: =SUM(G18:G19)
A21: E · 漂流墙 💌 | B21: 虚拟礼物-糖果档 | C21: 0.6 | D21: 0.02 | E21: ='01-核心假设'!$B$5*'01-核心假设'!$C$26*D21 | F21: =C21*E21 | G21: =F21*'01-核心假设'!$B$4 | H21: 0.6 元档
B22: 虚拟礼物-抱抱档 | C22: 1.9 | D22: 0.008 | E22: ='01-核心假设'!$B$5*'01-核心假设'!$C$26*D22 | F22: =C22*E22 | G22: =F22*'01-核心假设'!$B$4 | H22: 1.9 元档
B23: 虚拟礼物-烛光档 | C23: 9.9 | D23: 0.002 | E23: ='01-核心假设'!$B$5*'01-核心假设'!$C$26*D23 | F23: =C23*E23 | G23: =F23*'01-核心假设'!$B$4 | H23: 9.9 元档
A24: E 小计 | E24: =SUM(E21:E23) | F24: =SUM(F21:F23) | G24: =SUM(G21:G23)
A25: 单点合计 | E25: =SUM(E6,E10,E17,E20,E24) | F25: =SUM(F6,F10,F17,F20,F24) | G25: =SUM(G6,G10,G17,G20,G24)
A26: 整体付费率(日付费人数 / 基准DAU, 同一用户多点付费未去重, 为上限) | G26: =E25/'01-核心假设'!$B$5 | H26: 对标 PRD ≥3%
A27: 单点月 ARPU(单点月流水 / 基准DAU) | G27: =G25/'01-核心假设'!$B$5 | H27: 对标 PRD ≥8 元(含会员后)

Sheet 03-交叉转化敏感度
A1: 03 · 交叉转化敏感度分析 — 「情绪超市」核心杠杆
A2: 逻辑: 用户从来源模块被引流到去向模块后, 按去向模块的付费率与 ARPPU 产生增量收入。增量 = DAU × 来源渗透率 × 交叉转化率 × 去向付费率 × 去向ARPPU × 天数。
A3: 一、模块付费效率(引用 02 表自动计算)
A4: 模块 | B4: 日访客(人) | C4: 日付费人数 | D4: 付费率 | E4: 月流水(元) | F4: ARPPU(元/付费用户·月)
A5: A · 深夜信箱 | B5: ='01-核心假设'!$B$5*'01-核心假设'!$C$22 | C5: ='02-模块收入模型'!$E$6 | D5: =C5/B5 | E5: ='02-模块收入模型'!$G$6 | F5: =E5/(C5*'01-核心假设'!$B$4)
A6: B · 摆烂许可证 | B6: ='01-核心假设'!$B$5*'01-核心假设'!$C$23 | C6: ='02-模块收入模型'!$E$10 | D6: =C6/B6 | E6: ='02-模块收入模型'!$G$10 | F6: =E6/(C6*'01-核心假设'!$B$4)
A7: C · 塔罗盲盒 | B7: ='01-核心假设'!$B$5*'01-核心假设'!$C$24 | C7: ='02-模块收入模型'!$E$17 | D7: =C7/B7 | E7: ='02-模块收入模型'!$G$17 | F7: =E7/(C7*'01-核心假设'!$B$4)
A8: D · 许愿池 | B8: ='01-核心假设'!$B$5*'01-核心假设'!$C$25 | C8: ='02-模块收入模型'!$E$20 | D8: =C8/B8 | E8: ='02-模块收入模型'!$G$20 | F8: =E8/(C8*'01-核心假设'!$B$4)
A9: E · 漂流墙 | B9: ='01-核心假设'!$B$5*'01-核心假设'!$C$26 | C9: ='02-模块收入模型'!$E$24 | D9: =C9/B9 | E9: ='02-模块收入模型'!$G$24 | F9: =E9/(C9*'01-核心假设'!$B$4)
A11: 二、交叉转化矩阵(每日: 从「行」来源模块进入「列」去向模块的转化率, 黄色可调)
A12: 来源 ↓ / 去向 → | B12: A | C12: B | D12: C | E12: D | F12: E
A13: A | B13: — | C13: 0.03 | D13: 0.05 | E13: 0.02 | F13: 0.08
A14: B | B14: 0.01 | C14: — | D14: 0.02 | E14: 0.02 | F14: 0.01
A15: C | B15: 0.02 | C15: 0.01 | D15: — | E15: 0.04 | F15: 0.01
A16: D | B16: 0.01 | C16: 0.02 | D16: 0.03 | E16: — | F16: 0.01
A17: E | B17: 0.05 | C17: 0.01 | D17: 0.02 | E17: 0.02 | F17: —
A18: 依据: A→E 最高(写信可直接「漂流」到墙, PRD 原生动线); A→C 次之(深夜 emo 写信后顺手抽牌); C→D(塔罗结果引导许愿); E→A(看墙引发倾诉欲)。
A20: 三、交叉转化增量测算(按基准 DAU; 行已按增量从大到小排序 → 最上方即最大杠杆)
A21: 路径 | B21: 转化率 | C21: 日交叉引流(人) | D21: 去向付费率 | E21: 去向ARPPU(元) | F21: 日增量付费(人) | G21: 月增量流水(元)
A22: A → C | B22: =$D$13 | C22: ='01-核心假设'!$B$5*'01-核心假设'!$C$22*B22 | D22: =$D$7 | E22: =$F$7 | F22: =C22*D22 | G22: =F22*E22*'01-核心假设'!$B$4
A23: D → C | B23: =$D$16 | C23: ='01-核心假设'!$B$5*'01-核心假设'!$C$25*B23 | D23: =$D$7 | E23: =$F$7 | F23: =C23*D23 | G23: =F23*E23*'01-核心假设'!$B$4
A24: B → C | B24: =$D$14 | C24: ='01-核心假设'!$B$5*'01-核心假设'!$C$23*B24 | D24: =$D$7 | E24: =$F$7 | F24: =C24*D24 | G24: =F24*E24*'01-核心假设'!$B$4
A25: E → C | B25: =$D$17 | C25: ='01-核心假设'!$B$5*'01-核心假设'!$C$26*B25 | D25: =$D$7 | E25: =$F$7 | F25: =C25*D25 | G25: =F25*E25*'01-核心假设'!$B$4
A26: E → A | B26: =$B$17 | C26: ='01-核心假设'!$B$5*'01-核心假设'!$C$26*B26 | D26: =$D$5 | E26: =$F$5 | F26: =C26*D26 | G26: =F26*E26*'01-核心假设'!$B$4
A27: A → E | B27: =$F$13 | C27: ='01-核心假设'!$B$5*'01-核心假设'!$C$22*B27 | D27: =$D$9 | E27: =$F$9 | F27: =C27*D27 | G27: =F27*E27*'01-核心假设'!$B$4
A28: B → D | B28: =$E$14 | C28: ='01-核心假设'!$B$5*'01-核心假设'!$C$23*B28 | D28: =$D$8 | E28: =$F$8 | F28: =C28*D28 | G28: =F28*E28*'01-核心假设'!$B$4
A29: C → D | B29: =$E$15 | C29: ='01-核心假设'!$B$5*'01-核心假设'!$C$24*B29 | D29: =$D$8 | E29: =$F$8 | F29: =C29*D29 | G29: =F29*E29*'01-核心假设'!$B$4
A30: A → B | B30: =$C$13 | C30: ='01-核心假设'!$B$5*'01-核心假设'!$C$22*B30 | D30: =$D$6 | E30: =$F$6 | F30: =C30*D30 | G30: =F30*E30*'01-核心假设'!$B$4
A31: B → A | B31: =$B$14 | C31: ='01-核心假设'!$B$5*'01-核心假设'!$C$23*B31 | D31: =$D$5 | E31: =$F$5 | F31: =C31*D31 | G31: =F31*E31*'01-核心假设'!$B$4
A32: C → A | B32: =$B$15 | C32: ='01-核心假设'!$B$5*'01-核心假设'!$C$24*B32 | D32: =$D$5 | E32: =$F$5 | F32: =C32*D32 | G32: =F32*E32*'01-核心假设'!$B$4
A33: E → D | B33: =$E$17 | C33: ='01-核心假设'!$B$5*'01-核心假设'!$C$26*B33 | D33: =$D$8 | E33: =$F$8 | F33: =C33*D33 | G33: =F33*E33*'01-核心假设'!$B$4
A34: D → B | B34: =$C$16 | C34: ='01-核心假设'!$B$5*'01-核心假设'!$C$25*B34 | D34: =$D$6 | E34: =$F$6 | F34: =C34*D34 | G34: =F34*E34*'01-核心假设'!$B$4
A35: D → A | B35: =$B$16 | C35: ='01-核心假设'!$B$5*'01-核心假设'!$C$25*B35 | D35: =$D$5 | E35: =$F$5 | F35: =C35*D35 | G35: =F35*E35*'01-核心假设'!$B$4
A36: A → D | B36: =$E$13 | C36: ='01-核心假设'!$B$5*'01-核心假设'!$C$22*B36 | D36: =$D$8 | E36: =$F$8 | F36: =C36*D36 | G36: =F36*E36*'01-核心假设'!$B$4
A37: E → B | B37: =$C$17 | C37: ='01-核心假设'!$B$5*'01-核心假设'!$C$26*B37 | D37: =$D$6 | E37: =$F$6 | F37: =C37*D37 | G37: =F37*E37*'01-核心假设'!$B$4
A38: C → B | B38: =$C$15 | C38: ='01-核心假设'!$B$5*'01-核心假设'!$C$24*B38 | D38: =$D$6 | E38: =$F$6 | F38: =C38*D38 | G38: =F38*E38*'01-核心假设'!$B$4
A39: B → E | B39: =$F$14 | C39: ='01-核心假设'!$B$5*'01-核心假设'!$C$23*B39 | D39: =$D$9 | E39: =$F$9 | F39: =C39*D39 | G39: =F39*E39*'01-核心假设'!$B$4
A40: D → E | B40: =$F$16 | C40: ='01-核心假设'!$B$5*'01-核心假设'!$C$25*B40 | D40: =$D$9 | E40: =$F$9 | F40: =C40*D40 | G40: =F40*E40*'01-核心假设'!$B$4
A41: C → E | B41: =$F$15 | C41: ='01-核心假设'!$B$5*'01-核心假设'!$C$24*B41 | D41: =$D$9 | E41: =$F$9 | F41: =C41*D41 | G41: =F41*E41*'01-核心假设'!$B$4
A42: 交叉转化月增量合计(基准 DAU) | F42: =SUM(F22:F41) | G42: =SUM(G22:G41)
...

Sheet 04-会员模型
A1: 04 · 会员模型 — 会员 vs 单点付费
A3: 一、会员价格假设(引用 01 表)
A4: 月卡价格(元) | B4: ='01-核心假设'!$B$8 | C4: PRD: 19 元/月
A5: 年卡价格(元) | B5: ='01-核心假设'!$B$9 | C5: PRD: 128 元/年
A6: 月卡购买占比 | B6: ='01-核心假设'!$B$11 | C6: 可在 01 表修改
A7: 会员月均摊销 ARPU(元) | B7: ='01-核心假设'!$B$10 | C7: =19×70% + 128/12×30% ≈ 16.5
A9: 二、会员月收入敏感度(元/月): 会员转化率 × DAU
A10: 会员转化率 ＼ DAU | B10: ='01-核心假设'!$B$15 | C10: ='01-核心假设'!$B$16 | D10: ='01-核心假设'!$B$17 | E10: ='01-核心假设'!$B$18
A11: 0.005 | B11: =B$10*$A11*'01-核心假设'!$B$10 | C11: =C$10*$A11*'01-核心假设'!$B$10 | D11: =D$10*$A11*'01-核心假设'!$B$10 | E11: =E$10*$A11*'01-核心假设'!$B$10
A12: 0.01 | B12: =B$10*$A12*'01-核心假设'!$B$10 | C12: =C$10*$A12*'01-核心假设'!$B$10 | D12: =D$10*$A12*'01-核心假设'!$B$10 | E12: =E$10*$A12*'01-核心假设'!$B$10
A13: ='01-核心假设'!$B$29 | B13: =B$10*$A13*'01-核心假设'!$B$10 | C13: =C$10*$A13*'01-核心假设'!$B$10 | D13: =D$10*$A13*'01-核心假设'!$B$10 | E13: =E$10*$A13*'01-核心假设'!$B$10
A14: 0.03 | B14: =B$10*$A14*'01-核心假设'!$B$10 | C14: =C$10*$A14*'01-核心假设'!$B$10 | D14: =D$10*$A14*'01-核心假设'!$B$10 | E14: =E$10*$A14*'01-核心假设'!$B$10
A15: 第 3 行 1.5% 引用 01 表 PRD 目标转化率, 改 01 表即联动。
A17: 三、会员 vs 单点(基准 DAU)
A18: 单点月收入(元) | B18: ='02-模块收入模型'!$G$25 | C18: 02 表合计
A19: 会员月收入(元, 1.5% 转化) | B19: ='01-核心假设'!$B$5*'01-核心假设'!$B$29*'01-核心假设'!$B$10 | C19: =DAU × 转化率 × 会员月ARPU
A20: 交叉转化月增量(元) | B20: ='03-交叉转化敏感度'!$G$42 | C20: 03 表合计
A21: 合计月收入(元) | B21: =SUM(B18:B20)
A22: 会员收入占比 | B22: =B19/B21
A23: 付费会员数(人) | B23: ='01-核心假设'!$B$5*'01-核心假设'!$B$29
A24: 其中: 月卡收入(元) | B24: =B23*'01-核心假设'!$B$11*'01-核心假设'!$B$8
A25: 其中: 年卡收入(月摊销, 元) | B25: =B23*(1-'01-核心假设'!$B$11)*'01-核心假设'!$B$9/12
A27: 四、蚕食提示(会员权益含 A 无限回信 / C 免费单张, 会替代部分单点)
A28: 蚕食率假设(会员原单点消费被替代比例) | B28: 0.15
A29: 会员净增收(元) = 会员收入 − 会员数×单点月ARPU×蚕食率 | B29: =B19-B23*'02-模块收入模型'!$G$27*B28
A30: 即便如此, 会员的留存价值(不限量权益锁粘性)通常高于单点损失, 且年卡预收改善现金流。

Sheet 05-12个月预测
A1: 05 · 12 个月收入预测(按 PRD 里程碑节奏)
A2: 模块节奏: M1 仅 B → M2 加 A、C → M3 加 D → M4 加 E → M6 起会员体系(v2.0)。收入系数 = 当月已上线模块月流水 ÷ 全模块月流水(引用 02 表)。
A3: 月份 | B3: 里程碑 | C3: 当月已上线模块 | D3: 收入系数 | E3: DAU | F3: 单点月收入(元) | G3: 会员转化率 | H3: 会员月收入(元) | I3: 交叉系数 | J3: 交叉增量(元) | K3: 总月收入(元) | L3: 累计收入(元)
A4: M1 | B4: MVP(W1-2): 摆烂+首页 | C4: B | D4: ='02-模块收入模型'!$G$10/'02-模块收入模型'!$G$25 | E4: 1000 | F4: =D4*E4/'01-核心假设'!$B$5*'02-模块收入模型'!$G$25 | G4: 0 | H4: =E4*G4*'01-核心假设'!$B$10 | I4: 0 | J4: =F4*I4*'03-交叉转化敏感度'!$B$44 | K4: =F4+H4+J4 | L4: =K4
A5: M2 | B5: v1.1 信箱(W3-6) + v1.2 塔罗(M2) | C5: A+B+C | D5: =('02-模块收入模型'!$G$6+'02-模块收入模型'!$G$10+'02-模块收入模型'!$G$17)/'02-模块收入模型'!$G$25 | E5: 2500 | F5: =D5*E5/'01-核心假设'!$B$5*'02-模块收入模型'!$G$25 | G5: 0 | H5: =E5*G5*'01-核心假设'!$B$10 | I5: 0.5 | J5: =F5*I5*'03-交叉转化敏感度'!$B$44 | K5: =F5+H5+J5 | L5: =L4+K5
A6: M3 | B6: v1.3 许愿池 | C6: A+B+C+D | D6: =('02-模块收入模型'!$G$6+'02-模块收入模型'!$G$10+'02-模块收入模型'!$G$17+'02-模块收入模型'!$G$20)/'02-模块收入模型'!$G$25 | E6: 5000 | F6: =D6*E6/'01-核心假设'!$B$5*'02-模块收入模型'!$G$25 | G6: 0 | H6: =E6*G6*'01-核心假设'!$B$10 | I6: 1 | J6: =F6*I6*'03-交叉转化敏感度'!$B$44 | K6: =F6+H6+J6 | L6: =L5+K6
A7: M4 | B7: v1.4 漂流墙+UGC审核 | C7: 全部 | D7: =1 | E7: 6000 | F7: =D7*E7/'01-核心假设'!$B$5*'02-模块收入模型'!$G$25 | G7: 0 | H7: =E7*G7*'01-核心假设'!$B$10 | I7: 1 | J7: =F7*I7*'03-交叉转化敏感度'!$B$44 | K7: =F7+H7+J7 | L7: =L6+K7
A8: M5 | B8: 全模块精细化运营 | C8: 全部 | D8: =1 | E8: 7000 | F8: =D8*E8/'01-核心假设'!$B$5*'02-模块收入模型'!$G$25 | G8: 0 | H8: =E8*G8*'01-核心假设'!$B$10 | I8: 1 | J8: =F8*I8*'03-交叉转化敏感度'!$B$44 | K8: =F8+H8+J8 | L8: =L7+K8
A9: M6 | B9: v2.0 会员体系+周边电商 | C9: 全部+会员 | D9: =1 | E9: 8000 | F9: =D9*E9/'01-核心假设'!$B$5*'02-模块收入模型'!$G$25 | G9: 0.005 | H9: =E9*G9*'01-核心假设'!$B$10 | I9: 1 | J9: =F9*I9*'03-交叉转化敏感度'!$B$44 | K9: =F9+H9+J9 | L9: =L8+K9
A10: M7 | B10: 规模增长 | C10: 全部+会员 | D10: =1 | E10: 9000 | F10: =D10*E10/'01-核心假设'!$B$5*'02-模块收入模型'!$G$25 | G10: 0.01 | H10: =E10*G10*'01-核心假设'!$B$10 | I10: 1 | J10: =F10*I10*'03-交叉转化敏感度'!$B$44 | K10: =F10+H10+J10 | L10: =L9+K10
A11: M8 | B11: 规模增长 | C11: 全部+会员 | D11: =1 | E11: 10000 | F11: =D11*E11/'01-核心假设'!$B$5*'02-模块收入模型'!$G$25 | G11: 0.015 | H11: =E11*G11*'01-核心假设'!$B$10 | I11: 1 | J11: =F11*I11*'03-交叉转化敏感度'!$B$44 | K11: =F11+H11+J11 | L11: =L10+K11
A12: M9 | B12: 规模增长 | C12: 全部+会员 | D12: =1 | E12: 10500 | F12: =D12*E12/'01-核心假设'!$B$5*'02-模块收入模型'!$G$25 | G12: 0.015 | H12: =E12*G12*'01-核心假设'!$B$10 | I12: 1 | J12: =F12*I12*'03-交叉转化敏感度'!$B$44 | K12: =F12+H12+J12 | L12: =L11+K12
A13: M10 | B13: 规模增长 | C13: 全部+会员 | D13: =1 | E13: 11000 | F13: =D13*E13/'01-核心假设'!$B$5*'02-模块收入模型'!$G$25 | G13: 0.015 | H13: =E13*G13*'01-核心假设'!$B$10 | I13: 1 | J13: =F13*I13*'03-交叉转化敏感度'!$B$44 | K13: =F13+H13+J13 | L13: =L12+K13
A14: M11 | B14: 规模增长 | C14: 全部+会员 | D14: =1 | E14: 11500 | F14: =D14*E14/'01-核心假设'!$B$5*'02-模块收入模型'!$G$25 | G14: 0.015 | H14: =E14*G14*'01-核心假设'!$B$10 | I14: 1 | J14: =F14*I14*'03-交叉转化敏感度'!$B$44 | K14: =F14+H14+J14 | L14: =L13+K14
A15: M12 | B15: 规模增长 | C15: 全部+会员 | D15: =1 | E15: 12000 | F15: =D15*E15/'01-核心假设'!$B$5*'02-模块收入模型'!$G$25 | G15: 0.015 | H15: =E15*G15*'01-核心假设'!$B$10 | I15: 1 | J15: =F15*I15*'03-交叉转化敏感度'!$B$44 | K15: =F15+H15+J15 | L15: =L14+K15
A16: 全年合计(元) | K16: =SUM(K4:K15)
A18: DAU 假设: M3 达成 PRD 目标 5000; 会员转化率 M6 起步 0.5% → M8 起 1.5%(PRD 目标), 均为可调假设。

Sheet 06-汇总看板
A1: 06 · 汇总看板 — 关键结论数字
A3: 一、三档情景月收入(单点+会员+交叉)
A4: 情景 | B4: DAU | C4: 付费率假设 | D4: 单点月收入(元) | E4: 会员月收入(元) | F4: 交叉增量(元) | G4: 总月收入(元) | H4: 月ARPU(元)
A5: 保守 | B5: ='01-核心假设'!$B$16 | C5: 0.02 | D5: ='02-模块收入模型'!$G$25*(B5/'01-核心假设'!$B$5)*(C5/'01-核心假设'!$B$6) | E5: =B5*'01-核心假设'!$B$29*'01-核心假设'!$B$10 | F5: =D5*'03-交叉转化敏感度'!$B$44 | G5: =D5+E5+F5 | H5: =G5/B5
A6: 中性 | B6: ='01-核心假设'!$B$17 | C6: ='01-核心假设'!$B$6 | D6: ='02-模块收入模型'!$G$25*(B6/'01-核心假设'!$B$5)*(C6/'01-核心假设'!$B$6) | E6: =B6*'01-核心假设'!$B$29*'01-核心假设'!$B$10 | F6: =D6*'03-交叉转化敏感度'!$B$44 | G6: =D6+E6+F6 | H6: =G6/B6
A7: 乐观 | B7: ='01-核心假设'!$B$18 | C7: 0.045 | D7: ='02-模块收入模型'!$G$25*(B7/'01-核心假设'!$B$5)*(C7/'01-核心假设'!$B$6) | E7: =B7*'01-核心假设'!$B$29*'01-核心假设'!$B$10 | F7: =D7*'03-交叉转化敏感度'!$B$44 | G7: =D7+E7+F7 | H7: =G7/B7
A9: 二、月度成本估算(按中性情景 DAU)
A10: LLM API 成本(元) | B10: =B6*'01-核心假设'!$B$31*'01-核心假设'!$B$32*'01-核心假设'!$B$30*'01-核心假设'!$B$4 | C10: DAU×AI互动率×次数×单价×天数
A11: 内容审核成本(元) | B11: =B6*'01-核心假设'!$B$34*'01-核心假设'!$B$33*'01-核心假设'!$B$4 | C11: DAU×人均UGC条数×审核单价×天数
A12: 服务器成本(元) | B12: =IF(B6<='01-核心假设'!$A$39,'01-核心假设'!$B$39,IF(B6<='01-核心假设'!$A$40,'01-核心假设'!$B$40,IF(B6<='01-核心假设'!$A$41,'01-核心假设'!$B$41,IF(B6<='01-核心假设'!$A$42,'01-核心假设'!$B$42,'01-核心假设'!$B$43)))) | C12: 按 01 表分档
A13: 微信支付通道费(元) | B13: =G6*'01-核心假设'!$B$35 | C13: 中性总收入 × 0.6%
A14: 成本合计(元) | B14: =SUM(B10:B13)
A15: 月毛利(中性, 元) | B15: =G6-B14
A16: 毛利率 | B16: =B15/G6
A18: 三、盈亏平衡估算
A19: 变动成本率(LLM+审核+支付费 / 总收入) | B19: =(B10+B11+B13)/G6
A20: 盈亏平衡月收入(元) = 服务器成本 ÷ (1−变动成本率) | B20: =B12/(1-B19)
A21: 中性月 ARPU(元) | B21: =H6
A22: 盈亏平衡 DAU(人) ≈ 平衡收入 ÷ 月ARPU | B22: =B20/B21
A23: 注: 此模型毛利极高源于「全 AI 无真人」架构, 主要变动成本仅 LLM 调用; 未计入人力与投放成本。
A25: 四、关键结论
A26: ① 中性情景(DAU 5000、付费率 3%、会员转化 1.5%)月总收入约 4.3 万元, 月 ARPU ≈ 8.5 元, 达成 PRD ≥8 元目标。
A27: ② 交叉转化为第二增长曲线: 默认矩阵下月增收约占单点收入 13%, 且每 +1pp 交叉率 ≈ 基准 DAU 下月增收 ~1900 元(随 DAU 线性放大)。
A28: ③ 最大杠杆是「指向 C 塔罗」的交叉路径(A→C、D→C、B→C): 塔罗 ARPPU(≈23 元)为全模块最高, 引流 1 人顶漂流墙 15 人。
A29: ④ 会员收入占比仅 ~3%(1.5% 转化下), 短期是留存工具而非收入主力; 年卡占比提升可改善现金流与摊销 ARPU。
A30: ⑤ 盈亏平衡 DAU 仅约百人级(LLM 成本极低), 商业风险不在成本侧, 而在 DAU 增长与付费率兑现。
